<mujoco model="ur5e">
  <compiler angle="radian" meshdir="assets" autolimits="true"/>

  <!-- <option integrator="implicitfast"/> -->
  <option integrator="implicitfast" timestep="0.001" iterations="100" noslip_iterations="50" />
  <default>
    <default class="ur5e">
      <material specular="0.5" shininess="0.25"/>
      <joint axis="0 1 0" range="-6.28319 6.28319" armature="0.1"/>
      <general gaintype="fixed" biastype="affine" ctrlrange="-6.2831 6.2831" gainprm="2000" biasprm="0 -2000 -400"
        forcerange="-150 150"/>
      <default class="size3">
        <default class="size3_limited">
          <joint range="-3.1415 3.1415"/>
          <general ctrlrange="-3.1415 3.1415"/>
        </default>
      </default>
      <default class="size1">
        <general gainprm="500" biasprm="0 -500 -100" forcerange="-28 28"/>
      </default>
      <default class="visual">
        <geom type="mesh" contype="0" conaffinity="0" group="2"/>
      </default>
      <default class="collision">
        <geom type="capsule" group="3"/>
        <default class="eef_collision">
          <geom type="cylinder"/>
        </default>
      </default>
      <site size="0.001" rgba="0.5 0.5 0.5 0.3" group="4"/>
    </default>
  </default>

  <asset>
    <material class="ur5e" name="black" rgba="0.033 0.033 0.033 1"/>
    <material class="ur5e" name="jointgray" rgba="0.278 0.278 0.278 1"/>
    <material class="ur5e" name="linkgray" rgba="0.82 0.82 0.82 1"/>
    <material class="ur5e" name="urblue" rgba="0.49 0.678 0.8 1"/>

    <mesh file="base_0.obj"/>
    <mesh file="base_1.obj"/>
    <mesh file="shoulder_0.obj"/>
    <mesh file="shoulder_1.obj"/>
    <mesh file="shoulder_2.obj"/>
    <mesh file="upperarm_0.obj"/>
    <mesh file="upperarm_1.obj"/>
    <mesh file="upperarm_2.obj"/>
    <mesh file="upperarm_3.obj"/>
    <mesh file="forearm_0.obj"/>
    <mesh file="forearm_1.obj"/>
    <mesh file="forearm_2.obj"/>
    <mesh file="forearm_3.obj"/>
    <mesh file="wrist1_0.obj"/>
    <mesh file="wrist1_1.obj"/>
    <mesh file="wrist1_2.obj"/>
    <mesh file="wrist2_0.obj"/>
    <mesh file="wrist2_1.obj"/>
    <mesh file="wrist2_2.obj"/>
    <mesh file="wrist3.obj"/>
    <mesh name="robotiq_arg2f_base_link" file="robotiq_arg2f_base_link.stl"/>
    <mesh name="robotiq_arg2f_85_outer_knuckle" file="robotiq_arg2f_85_outer_knuckle.stl" scale="0.001 0.001 0.001"/>
    <mesh name="robotiq_arg2f_85_outer_finger" file="robotiq_arg2f_85_outer_finger.stl" scale="0.001 0.001 0.001"/>
    <mesh name="robotiq_arg2f_85_inner_finger" file="robotiq_arg2f_85_inner_finger.stl" scale="0.001 0.001 0.001"/>
    <mesh name="robotiq_arg2f_85_inner_knuckle" file="robotiq_arg2f_85_inner_knuckle.stl" scale="0.001 0.001 0.001"/>
    <mesh name="robotiq_arg2f_85_outer_knuckle_vis" file="robotiq_arg2f_85_outer_knuckle_vis.stl" scale="0.001 0.001 0.001"/>
    <mesh name="robotiq_arg2f_85_outer_finger_vis" file="robotiq_arg2f_85_outer_finger_vis.stl" scale="0.001 0.001 0.001"/>
    <mesh name="robotiq_arg2f_85_inner_finger_vis" file="robotiq_arg2f_85_inner_finger_vis.stl" scale="0.001 0.001 0.001"/>
    <mesh name="robotiq_arg2f_85_inner_knuckle_vis" file="robotiq_arg2f_85_inner_knuckle_vis.stl" scale="0.001 0.001 0.001"/>
    <material name="GriMat" specular="0.9" shininess="0.5" reflectance="0" rgba="0.1 0.1 0.1 1" emission="0.1"/>
    <material name="BasketMat" specular="0" shininess="0" reflectance="0" rgba="0.26 0.16 0.16796875 1" emission="0"/>
    <material name="Light" specular="0" shininess="0.6" reflectance="0.9" rgba="0.5 0.5 1 1" emission="0.7"/>
    
  </asset>

  <worldbody>
    <light name="spotlight" mode="targetbodycom" target="wrist_2_link" pos="0 -1 2"/>
    <body name="base" quat="0 0 0 -1" childclass="ur5e">
      <inertial mass="4.0" pos="0 0 0" diaginertia="0.00443333156 0.00443333156 0.0072"/>
      <geom mesh="base_0" material="black" class="visual"/>
      <geom mesh="base_1" material="jointgray" class="visual"/>
      <body name="shoulder_link" pos="0 0 0.163">
        <inertial mass="3.7" pos="0 0 0" diaginertia="0.0102675 0.0102675 0.00666"/>
        <joint name="shoulder_pan_joint" class="size3" axis="0 0 1"/>
        <geom mesh="shoulder_0" material="urblue" class="visual"/>
        <geom mesh="shoulder_1" material="black" class="visual"/>
        <geom mesh="shoulder_2" material="jointgray" class="visual"/>
        <geom class="collision" size="0.06 0.06" pos="0 0 -0.04"/>
        <body name="upper_arm_link" pos="0 0.138 0" quat="1 0 1 0">
          <inertial mass="8.393" pos="0 0 0.2125" diaginertia="0.133886 0.133886 0.0151074"/>
          <joint name="shoulder_lift_joint" class="size3"/>
          <geom mesh="upperarm_0" material="linkgray" class="visual"/>
          <geom mesh="upperarm_1" material="black" class="visual"/>
          <geom mesh="upperarm_2" material="jointgray" class="visual"/>
          <geom mesh="upperarm_3" material="urblue" class="visual"/>
          <geom class="collision" pos="0 -0.04 0" quat="1 1 0 0" size="0.06 0.06"/>
          <geom class="collision" size="0.05 0.2" pos="0 0 0.2"/>
          <body name="forearm_link" pos="0 -0.131 0.425">
            <inertial mass="2.275" pos="0 0 0.196" diaginertia="0.0311796 0.0311796 0.004095"/>
            <joint name="elbow_joint" class="size3_limited"/>
            <geom mesh="forearm_0" material="urblue" class="visual"/>
            <geom mesh="forearm_1" material="linkgray" class="visual"/>
            <geom mesh="forearm_2" material="black" class="visual"/>
            <geom mesh="forearm_3" material="jointgray" class="visual"/>
            <geom class="collision" pos="0 0.08 0" quat="1 1 0 0" size="0.055 0.06"/>
            <geom class="collision" size="0.038 0.19" pos="0 0 0.2"/>
            <body name="wrist_1_link" pos="0 0 0.392" quat="1 0 1 0">
              <inertial mass="1.219" pos="0 0.127 0" diaginertia="0.0025599 0.0025599 0.0021942"/>
              <joint name="wrist_1_joint" class="size1"/>
              <geom mesh="wrist1_0" material="black" class="visual"/>
              <geom mesh="wrist1_1" material="urblue" class="visual"/>
              <geom mesh="wrist1_2" material="jointgray" class="visual"/>
              <geom class="collision" pos="0 0.05 0" quat="1 1 0 0" size="0.04 0.07"/>
              <body name="wrist_2_link" pos="0 0.127 0">
                <inertial mass="1.219" pos="0 0 0.1" diaginertia="0.0025599 0.0025599 0.0021942"/>
                <joint name="wrist_2_joint" axis="0 0 1" class="size1"/>
                <geom mesh="wrist2_0" material="black" class="visual"/>
                <geom mesh="wrist2_1" material="urblue" class="visual"/>
                <geom mesh="wrist2_2" material="jointgray" class="visual"/>
                <geom class="collision" size="0.04 0.06" pos="0 0 0.04"/>
                <geom class="collision" pos="0 0.02 0.1" quat="1 1 0 0" size="0.04 0.04"/>
                <body name="wrist_3_link" pos="0 0 0.1">
                  <inertial mass="0.1889" pos="0 0.0771683 0" quat="1 0 0 1"
                    diaginertia="0.000132134 9.90863e-05 9.90863e-05"/>
                  <joint name="wrist_3_joint" class="size1"/>
                  <geom material="linkgray" mesh="wrist3" class="visual"/>
                  <geom class="eef_collision" pos="0 0.08 0" quat="1 1 0 0" size="0.04 0.02"/>
                  
                  <body name="ee_link" pos="0 0.0823 0" quat="1 0 0 0">
                    <inertial pos="0 0.0823 0" quat="1 0 0 0" mass="0" diaginertia="0 0 0"/>
                    <site name="attachment_site" pos="0 0.14 0" quat="0.9238795 0 0 -0.3826834" size="0.01" type="sphere"/>
                    
                    <body name="robotiq_85_adapter_link" pos="0 0.01 0" euler="-1.57 0 0">
                      <inertial pos="0 0 0" mass="0.01" diaginertia="0.001 0.001 0.001"/>
                      <geom type="mesh" contype="0" conaffinity="0" group="1" rgba="0.1 0.1 0.1 1" name="hand_visual" mesh="robotiq_arg2f_base_link"/>
                      <geom type="mesh" group="0" rgba="0.1 0.1 0.1 1" mesh="robotiq_arg2f_base_link" name="hand_collision"/>
                      
                      <body name="eef" pos="0 0 0.145" quat="0.707105 0 0 -0.707105">
                        <site name="ee_x" pos="0.1 0 0" size="0.005 .1" quat="0.707105 0 0.707108 0" rgba="1 0 0 0" type="cylinder" group="1"/>
                        <site name="ee_y" pos="0 0.1 0" size="0.005 .1" quat="0.707105 0.707108 0 0" rgba="0 1 0 0" type="cylinder" group="1"/>
                        <site name="ee_z" pos="0 0 0.1" size="0.005 .1" quat="1 0 0 0" rgba="0 0 1 0" type="cylinder" group="1"/>
                      </body>
                    
                      <body name="left_outer_knuckle" pos="0 -0.0306011 0.054904" quat="0 0 0 1">
                        <inertial pos="0.000163875 0.0554825 -0.0100755" quat="0.920541 0.390623 -0.00362953 0.00231744" mass="0.0311462" diaginertia="5.11372e-05 4.89464e-05 4.95906e-06"/>
                        <joint name="finger_joint" pos="0 0 0" axis="1 0 0" limited="true" range="0 0.8"/>
                        <geom type="mesh" contype="0" conaffinity="0" group="1" rgba="0.792157 0.819608 0.933333 1" name="left_outer_knuckle_visual" mesh="robotiq_arg2f_85_outer_knuckle_vis"/>
                        <geom pos="0 0.0315 -0.0041" type="mesh" contype="0" conaffinity="0" group="1" rgba="0.1 0.1 0.1 1" name="left_outer_finger_visual" mesh="robotiq_arg2f_85_outer_finger_vis"/>
                        
                        <body name="left_inner_finger" pos="0 0.0376 0.043">
                          <inertial pos="0.000199506 0.0032692 0.00175282" quat="0.933621 0.35825 -0.00273441 0.00104851" mass="0.0156391" diaginertia="1.57977e-05 1.51089e-05 1.4647e-06"/>
                          <joint name="left_inner_finger_joint" pos="0 0 0" axis="1 0 0" limited="true" range="-0.8757 0.8757"/>
                          <geom type="mesh" contype="0" conaffinity="0" group="1" rgba="0.1 0.1 0.1 1" name="left_inner_finger_visual" mesh="robotiq_arg2f_85_inner_finger_vis"/>
                          <geom size="0.011 0.003175 0.01875" pos="0 -0.0220203 0.03242" type="box" contype="1" conaffinity="1" group="0" rgba="0.9 0.9 0.9 1" name="left_fingertip" solimp="0.95 0.99 0.001" solref="0.002 1" condim="6" friction="1 0.005 0.0001"/>
                        </body>
                      </body>
                      <body name="left_inner_knuckle" pos="0 -0.0127 0.06142" quat="0 0 0 1">
                        <inertial pos="0.000123012 0.0507851 0.00103969" quat="0.497203 0.502496 -0.507943 0.492221" mass="0.0271177" diaginertia="2.83809e-05 2.61936e-05 2.81319e-06"/>
                        <joint name="left_inner_knuckle_joint" pos="0 0 0" axis="1 0 0" limited="true" range="0 0.8757"/>
                        <geom type="mesh" contype="0" conaffinity="0" group="1" rgba="0.1 0.1 0.1 1" name="left_inner_knuckle_visual" mesh="robotiq_arg2f_85_inner_knuckle_vis"/>
                      </body>
                      <body name="right_outer_knuckle" pos="0 0.0306011 0.054904">
                        <inertial pos="0.000163875 0.0554825 -0.0100755" quat="0.920541 0.390623 -0.00362953 0.00231744" mass="0.0311462" diaginertia="5.11372e-05 4.89464e-05 4.95906e-06"/>
                        <joint name="right_outer_knuckle_joint" pos="0 0 0" axis="1 0 0" limited="true" range="0 0.8"/>
                        <geom type="mesh" contype="0" conaffinity="0" group="1" rgba="0.792157 0.819608 0.933333 1" name="right_outer_knuckle_visual" mesh="robotiq_arg2f_85_outer_knuckle_vis"/>
                        <geom pos="0 0.0315 -0.0041" type="mesh" contype="0" conaffinity="0" group="1" rgba="0.1 0.1 0.1 1" name="right_outer_finger_visual" mesh="robotiq_arg2f_85_outer_finger_vis"/>
                        
                        <body name="right_inner_finger" pos="0 0.0376 0.043">
                          <inertial pos="0.000199506 0.0032692 0.00175282" quat="0.933621 0.35825 -0.00273441 0.00104851" mass="0.0156391" diaginertia="1.57977e-05 1.51089e-05 1.4647e-06"/>
                          <joint name="right_inner_finger_joint" pos="0 0 0" axis="1 0 0" limited="true" range="-0.8757 0.8757"/>
                          <geom type="mesh" contype="0" conaffinity="0" group="1" rgba="0.1 0.1 0.1 1" name="right_inner_finger_visual" mesh="robotiq_arg2f_85_inner_finger_vis"/>
                          <geom size="0.011 0.003175 0.01875" pos="0 -0.0220203 0.03242" type="box" contype="1" conaffinity="1" group="0" rgba="0.9 0.9 0.9 1" name="right_fingertip" solimp="0.95 0.99 0.001" solref="0.002 1" condim="6" friction="1 0.005 0.0001"/>
                        </body>
                      </body>
                      <body name="right_inner_knuckle" pos="0 0.0127 0.06142">
                        <inertial pos="0.000123012 0.0507851 0.00103969" quat="0.497203 0.502496 -0.507943 0.492221" mass="0.0271177" diaginertia="2.83809e-05 2.61936e-05 2.81319e-06"/>
                        <joint name="right_inner_knuckle_joint" pos="0 0 0" axis="1 0 0" limited="true" range="0 0.8757"/>
                        <geom type="mesh" contype="0" conaffinity="0" group="1" rgba="0.1 0.1 0.1 1" name="right_inner_knuckle_visual" mesh="robotiq_arg2f_85_inner_knuckle_vis"/>
                      </body>
                    </body>
                  </body>
                </body>
              </body>
            </body>
          </body>
        </body>
      </body>
    </body>
  </worldbody>

  <actuator>
    <general class="size3" name="shoulder_pan" joint="shoulder_pan_joint"/>
    <general class="size3" name="shoulder_lift" joint="shoulder_lift_joint"/>
    <general class="size3_limited" name="elbow" joint="elbow_joint"/>
    <general class="size1" name="wrist_1" joint="wrist_1_joint"/>
    <general class="size1" name="wrist_2" joint="wrist_2_joint"/>
    <general class="size1" name="wrist_3" joint="wrist_3_joint"/>
    <motor name="finger_joint_motor" joint="finger_joint" gear="50" ctrllimited="true" ctrlrange="-1 1"/>
  </actuator>

  <equality>
    <joint joint1="finger_joint" joint2="right_outer_knuckle_joint" polycoef="0 1 0 0 0"/>
    <joint joint1="finger_joint" joint2="left_inner_knuckle_joint" polycoef="0 1 0 0 0"/>
    <joint joint1="finger_joint" joint2="right_inner_knuckle_joint" polycoef="0 1 0 0 0"/>
    <joint joint1="finger_joint" joint2="left_inner_finger_joint" polycoef="0 -1 0 0 0"/>
    <joint joint1="finger_joint" joint2="right_inner_finger_joint" polycoef="0 -1 0 0 0"/>
  </equality>
</mujoco>
